{
 "cells": [
  {
   "cell_type": "code",
   "execution_count": 1,
   "metadata": {},
   "outputs": [
    {
     "name": "stderr",
     "output_type": "stream",
     "text": [
      "ERROR:root:Internal Python error in the inspect module.\n",
      "Below is the traceback from this internal error.\n",
      "\n",
      "ERROR:root:Internal Python error in the inspect module.\n",
      "Below is the traceback from this internal error.\n",
      "\n",
      "ERROR:root:Internal Python error in the inspect module.\n",
      "Below is the traceback from this internal error.\n",
      "\n"
     ]
    },
    {
     "name": "stdout",
     "output_type": "stream",
     "text": [
      "Traceback (most recent call last):\n",
      "  File \"c:\\Users\\Marcos\\miniconda3\\envs\\tf2\\lib\\site-packages\\IPython\\core\\interactiveshell.py\", line 3552, in run_code\n",
      "    exec(code_obj, self.user_global_ns, self.user_ns)\n",
      "  File \"C:\\Users\\Marcos\\AppData\\Local\\Temp\\ipykernel_5176\\1735728665.py\", line 2, in <module>\n",
      "    from tensorflow.keras.layers import MultiHeadAttention\n",
      "ImportError: cannot import name 'MultiHeadAttention' from 'tensorflow.keras.layers' (c:\\Users\\Marcos\\miniconda3\\envs\\tf2\\lib\\site-packages\\tensorflow_core\\python\\keras\\api\\_v2\\keras\\layers\\__init__.py)\n",
      "\n",
      "During handling of the above exception, another exception occurred:\n",
      "\n",
      "Traceback (most recent call last):\n",
      "  File \"c:\\Users\\Marcos\\miniconda3\\envs\\tf2\\lib\\site-packages\\IPython\\core\\interactiveshell.py\", line 2098, in showtraceback\n",
      "    stb = value._render_traceback_()\n",
      "AttributeError: 'ImportError' object has no attribute '_render_traceback_'\n",
      "\n",
      "During handling of the above exception, another exception occurred:\n",
      "\n",
      "Traceback (most recent call last):\n",
      "  File \"c:\\Users\\Marcos\\miniconda3\\envs\\tf2\\lib\\site-packages\\IPython\\core\\ultratb.py\", line 1101, in get_records\n",
      "    return _fixed_getinnerframes(etb, number_of_lines_of_context, tb_offset)\n",
      "  File \"c:\\Users\\Marcos\\miniconda3\\envs\\tf2\\lib\\site-packages\\IPython\\core\\ultratb.py\", line 248, in wrapped\n",
      "    return f(*args, **kwargs)\n",
      "  File \"c:\\Users\\Marcos\\miniconda3\\envs\\tf2\\lib\\site-packages\\IPython\\core\\ultratb.py\", line 281, in _fixed_getinnerframes\n",
      "    records = fix_frame_records_filenames(inspect.getinnerframes(etb, context))\n",
      "  File \"c:\\Users\\Marcos\\miniconda3\\envs\\tf2\\lib\\inspect.py\", line 1502, in getinnerframes\n",
      "    frameinfo = (tb.tb_frame,) + getframeinfo(tb, context)\n",
      "  File \"c:\\Users\\Marcos\\miniconda3\\envs\\tf2\\lib\\inspect.py\", line 1460, in getframeinfo\n",
      "    filename = getsourcefile(frame) or getfile(frame)\n",
      "  File \"c:\\Users\\Marcos\\miniconda3\\envs\\tf2\\lib\\inspect.py\", line 696, in getsourcefile\n",
      "    if getattr(getmodule(object, filename), '__loader__', None) is not None:\n",
      "  File \"c:\\Users\\Marcos\\miniconda3\\envs\\tf2\\lib\\inspect.py\", line 733, in getmodule\n",
      "    if ismodule(module) and hasattr(module, '__file__'):\n",
      "  File \"c:\\Users\\Marcos\\miniconda3\\envs\\tf2\\lib\\site-packages\\tensorflow\\__init__.py\", line 50, in __getattr__\n",
      "    module = self._load()\n",
      "  File \"c:\\Users\\Marcos\\miniconda3\\envs\\tf2\\lib\\site-packages\\tensorflow\\__init__.py\", line 44, in _load\n",
      "    module = _importlib.import_module(self.__name__)\n",
      "  File \"c:\\Users\\Marcos\\miniconda3\\envs\\tf2\\lib\\importlib\\__init__.py\", line 127, in import_module\n",
      "    return _bootstrap._gcd_import(name[level:], package, level)\n",
      "  File \"<frozen importlib._bootstrap>\", line 1006, in _gcd_import\n",
      "  File \"<frozen importlib._bootstrap>\", line 983, in _find_and_load\n",
      "  File \"<frozen importlib._bootstrap>\", line 965, in _find_and_load_unlocked\n",
      "ModuleNotFoundError: No module named 'tensorflow_core.estimator'\n",
      "Traceback (most recent call last):\n",
      "  File \"c:\\Users\\Marcos\\miniconda3\\envs\\tf2\\lib\\site-packages\\IPython\\core\\interactiveshell.py\", line 3552, in run_code\n",
      "    exec(code_obj, self.user_global_ns, self.user_ns)\n",
      "  File \"C:\\Users\\Marcos\\AppData\\Local\\Temp\\ipykernel_5176\\1735728665.py\", line 2, in <module>\n",
      "    from tensorflow.keras.layers import MultiHeadAttention\n",
      "ImportError: cannot import name 'MultiHeadAttention' from 'tensorflow.keras.layers' (c:\\Users\\Marcos\\miniconda3\\envs\\tf2\\lib\\site-packages\\tensorflow_core\\python\\keras\\api\\_v2\\keras\\layers\\__init__.py)\n",
      "\n",
      "During handling of the above exception, another exception occurred:\n",
      "\n",
      "Traceback (most recent call last):\n",
      "  File \"c:\\Users\\Marcos\\miniconda3\\envs\\tf2\\lib\\site-packages\\IPython\\core\\interactiveshell.py\", line 2098, in showtraceback\n",
      "    stb = value._render_traceback_()\n",
      "AttributeError: 'ImportError' object has no attribute '_render_traceback_'\n",
      "\n",
      "During handling of the above exception, another exception occurred:\n",
      "\n",
      "Traceback (most recent call last):\n",
      "  File \"c:\\Users\\Marcos\\miniconda3\\envs\\tf2\\lib\\site-packages\\IPython\\core\\interactiveshell.py\", line 3472, in run_ast_nodes\n",
      "    if (await self.run_code(code, result,  async_=asy)):\n",
      "  File \"c:\\Users\\Marcos\\miniconda3\\envs\\tf2\\lib\\site-packages\\IPython\\core\\interactiveshell.py\", line 3569, in run_code\n",
      "    self.showtraceback(running_compiled_code=True)\n",
      "  File \"c:\\Users\\Marcos\\miniconda3\\envs\\tf2\\lib\\site-packages\\IPython\\core\\interactiveshell.py\", line 2101, in showtraceback\n",
      "    value, tb, tb_offset=tb_offset)\n",
      "  File \"c:\\Users\\Marcos\\miniconda3\\envs\\tf2\\lib\\site-packages\\IPython\\core\\ultratb.py\", line 1368, in structured_traceback\n",
      "    self, etype, value, tb, tb_offset, number_of_lines_of_context)\n",
      "  File \"c:\\Users\\Marcos\\miniconda3\\envs\\tf2\\lib\\site-packages\\IPython\\core\\ultratb.py\", line 1268, in structured_traceback\n",
      "    self, etype, value, tb, tb_offset, number_of_lines_of_context\n",
      "  File \"c:\\Users\\Marcos\\miniconda3\\envs\\tf2\\lib\\site-packages\\IPython\\core\\ultratb.py\", line 1125, in structured_traceback\n",
      "    tb_offset)\n",
      "  File \"c:\\Users\\Marcos\\miniconda3\\envs\\tf2\\lib\\site-packages\\IPython\\core\\ultratb.py\", line 1082, in format_exception_as_a_whole\n",
      "    last_unique, recursion_repeat = find_recursion(orig_etype, evalue, records)\n",
      "  File \"c:\\Users\\Marcos\\miniconda3\\envs\\tf2\\lib\\site-packages\\IPython\\core\\ultratb.py\", line 382, in find_recursion\n",
      "    return len(records), 0\n",
      "TypeError: object of type 'NoneType' has no len()\n",
      "\n",
      "During handling of the above exception, another exception occurred:\n",
      "\n",
      "Traceback (most recent call last):\n",
      "  File \"c:\\Users\\Marcos\\miniconda3\\envs\\tf2\\lib\\site-packages\\IPython\\core\\interactiveshell.py\", line 2098, in showtraceback\n",
      "    stb = value._render_traceback_()\n",
      "AttributeError: 'TypeError' object has no attribute '_render_traceback_'\n",
      "\n",
      "During handling of the above exception, another exception occurred:\n",
      "\n",
      "Traceback (most recent call last):\n",
      "  File \"c:\\Users\\Marcos\\miniconda3\\envs\\tf2\\lib\\site-packages\\IPython\\core\\ultratb.py\", line 1101, in get_records\n",
      "    return _fixed_getinnerframes(etb, number_of_lines_of_context, tb_offset)\n",
      "  File \"c:\\Users\\Marcos\\miniconda3\\envs\\tf2\\lib\\site-packages\\IPython\\core\\ultratb.py\", line 248, in wrapped\n",
      "    return f(*args, **kwargs)\n",
      "  File \"c:\\Users\\Marcos\\miniconda3\\envs\\tf2\\lib\\site-packages\\IPython\\core\\ultratb.py\", line 281, in _fixed_getinnerframes\n",
      "    records = fix_frame_records_filenames(inspect.getinnerframes(etb, context))\n",
      "  File \"c:\\Users\\Marcos\\miniconda3\\envs\\tf2\\lib\\inspect.py\", line 1502, in getinnerframes\n",
      "    frameinfo = (tb.tb_frame,) + getframeinfo(tb, context)\n",
      "  File \"c:\\Users\\Marcos\\miniconda3\\envs\\tf2\\lib\\inspect.py\", line 1460, in getframeinfo\n",
      "    filename = getsourcefile(frame) or getfile(frame)\n",
      "  File \"c:\\Users\\Marcos\\miniconda3\\envs\\tf2\\lib\\inspect.py\", line 696, in getsourcefile\n",
      "    if getattr(getmodule(object, filename), '__loader__', None) is not None:\n",
      "  File \"c:\\Users\\Marcos\\miniconda3\\envs\\tf2\\lib\\inspect.py\", line 733, in getmodule\n",
      "    if ismodule(module) and hasattr(module, '__file__'):\n",
      "  File \"c:\\Users\\Marcos\\miniconda3\\envs\\tf2\\lib\\site-packages\\tensorflow\\__init__.py\", line 50, in __getattr__\n",
      "    module = self._load()\n",
      "  File \"c:\\Users\\Marcos\\miniconda3\\envs\\tf2\\lib\\site-packages\\tensorflow\\__init__.py\", line 44, in _load\n",
      "    module = _importlib.import_module(self.__name__)\n",
      "  File \"c:\\Users\\Marcos\\miniconda3\\envs\\tf2\\lib\\importlib\\__init__.py\", line 127, in import_module\n",
      "    return _bootstrap._gcd_import(name[level:], package, level)\n",
      "  File \"<frozen importlib._bootstrap>\", line 1006, in _gcd_import\n",
      "  File \"<frozen importlib._bootstrap>\", line 983, in _find_and_load\n",
      "  File \"<frozen importlib._bootstrap>\", line 965, in _find_and_load_unlocked\n",
      "ModuleNotFoundError: No module named 'tensorflow_core.estimator'\n",
      "Traceback (most recent call last):\n",
      "  File \"c:\\Users\\Marcos\\miniconda3\\envs\\tf2\\lib\\site-packages\\IPython\\core\\interactiveshell.py\", line 3552, in run_code\n",
      "    exec(code_obj, self.user_global_ns, self.user_ns)\n",
      "  File \"C:\\Users\\Marcos\\AppData\\Local\\Temp\\ipykernel_5176\\1735728665.py\", line 2, in <module>\n",
      "    from tensorflow.keras.layers import MultiHeadAttention\n",
      "ImportError: cannot import name 'MultiHeadAttention' from 'tensorflow.keras.layers' (c:\\Users\\Marcos\\miniconda3\\envs\\tf2\\lib\\site-packages\\tensorflow_core\\python\\keras\\api\\_v2\\keras\\layers\\__init__.py)\n",
      "\n",
      "During handling of the above exception, another exception occurred:\n",
      "\n",
      "Traceback (most recent call last):\n",
      "  File \"c:\\Users\\Marcos\\miniconda3\\envs\\tf2\\lib\\site-packages\\IPython\\core\\interactiveshell.py\", line 2098, in showtraceback\n",
      "    stb = value._render_traceback_()\n",
      "AttributeError: 'ImportError' object has no attribute '_render_traceback_'\n",
      "\n",
      "During handling of the above exception, another exception occurred:\n",
      "\n",
      "Traceback (most recent call last):\n",
      "  File \"c:\\Users\\Marcos\\miniconda3\\envs\\tf2\\lib\\site-packages\\IPython\\core\\interactiveshell.py\", line 3472, in run_ast_nodes\n",
      "    if (await self.run_code(code, result,  async_=asy)):\n",
      "  File \"c:\\Users\\Marcos\\miniconda3\\envs\\tf2\\lib\\site-packages\\IPython\\core\\interactiveshell.py\", line 3569, in run_code\n",
      "    self.showtraceback(running_compiled_code=True)\n",
      "  File \"c:\\Users\\Marcos\\miniconda3\\envs\\tf2\\lib\\site-packages\\IPython\\core\\interactiveshell.py\", line 2101, in showtraceback\n",
      "    value, tb, tb_offset=tb_offset)\n",
      "  File \"c:\\Users\\Marcos\\miniconda3\\envs\\tf2\\lib\\site-packages\\IPython\\core\\ultratb.py\", line 1368, in structured_traceback\n",
      "    self, etype, value, tb, tb_offset, number_of_lines_of_context)\n",
      "  File \"c:\\Users\\Marcos\\miniconda3\\envs\\tf2\\lib\\site-packages\\IPython\\core\\ultratb.py\", line 1268, in structured_traceback\n",
      "    self, etype, value, tb, tb_offset, number_of_lines_of_context\n",
      "  File \"c:\\Users\\Marcos\\miniconda3\\envs\\tf2\\lib\\site-packages\\IPython\\core\\ultratb.py\", line 1125, in structured_traceback\n",
      "    tb_offset)\n",
      "  File \"c:\\Users\\Marcos\\miniconda3\\envs\\tf2\\lib\\site-packages\\IPython\\core\\ultratb.py\", line 1082, in format_exception_as_a_whole\n",
      "    last_unique, recursion_repeat = find_recursion(orig_etype, evalue, records)\n",
      "  File \"c:\\Users\\Marcos\\miniconda3\\envs\\tf2\\lib\\site-packages\\IPython\\core\\ultratb.py\", line 382, in find_recursion\n",
      "    return len(records), 0\n",
      "TypeError: object of type 'NoneType' has no len()\n",
      "\n",
      "During handling of the above exception, another exception occurred:\n",
      "\n",
      "Traceback (most recent call last):\n",
      "  File \"c:\\Users\\Marcos\\miniconda3\\envs\\tf2\\lib\\site-packages\\IPython\\core\\interactiveshell.py\", line 2098, in showtraceback\n",
      "    stb = value._render_traceback_()\n",
      "AttributeError: 'TypeError' object has no attribute '_render_traceback_'\n",
      "\n",
      "During handling of the above exception, another exception occurred:\n",
      "\n",
      "Traceback (most recent call last):\n",
      "  File \"c:\\Users\\Marcos\\miniconda3\\envs\\tf2\\lib\\site-packages\\IPython\\core\\interactiveshell.py\", line 3029, in _run_cell\n",
      "    return runner(coro)\n",
      "  File \"c:\\Users\\Marcos\\miniconda3\\envs\\tf2\\lib\\site-packages\\IPython\\core\\async_helpers.py\", line 78, in _pseudo_sync_runner\n",
      "    coro.send(None)\n",
      "  File \"c:\\Users\\Marcos\\miniconda3\\envs\\tf2\\lib\\site-packages\\IPython\\core\\interactiveshell.py\", line 3257, in run_cell_async\n",
      "    interactivity=interactivity, compiler=compiler, result=result)\n",
      "  File \"c:\\Users\\Marcos\\miniconda3\\envs\\tf2\\lib\\site-packages\\IPython\\core\\interactiveshell.py\", line 3491, in run_ast_nodes\n",
      "    self.showtraceback()\n",
      "  File \"c:\\Users\\Marcos\\miniconda3\\envs\\tf2\\lib\\site-packages\\IPython\\core\\interactiveshell.py\", line 2101, in showtraceback\n",
      "    value, tb, tb_offset=tb_offset)\n",
      "  File \"c:\\Users\\Marcos\\miniconda3\\envs\\tf2\\lib\\site-packages\\IPython\\core\\ultratb.py\", line 1368, in structured_traceback\n",
      "    self, etype, value, tb, tb_offset, number_of_lines_of_context)\n",
      "  File \"c:\\Users\\Marcos\\miniconda3\\envs\\tf2\\lib\\site-packages\\IPython\\core\\ultratb.py\", line 1268, in structured_traceback\n",
      "    self, etype, value, tb, tb_offset, number_of_lines_of_context\n",
      "  File \"c:\\Users\\Marcos\\miniconda3\\envs\\tf2\\lib\\site-packages\\IPython\\core\\ultratb.py\", line 1143, in structured_traceback\n",
      "    chained_exceptions_tb_offset)\n",
      "  File \"c:\\Users\\Marcos\\miniconda3\\envs\\tf2\\lib\\site-packages\\IPython\\core\\ultratb.py\", line 1082, in format_exception_as_a_whole\n",
      "    last_unique, recursion_repeat = find_recursion(orig_etype, evalue, records)\n",
      "  File \"c:\\Users\\Marcos\\miniconda3\\envs\\tf2\\lib\\site-packages\\IPython\\core\\ultratb.py\", line 382, in find_recursion\n",
      "    return len(records), 0\n",
      "TypeError: object of type 'NoneType' has no len()\n",
      "\n",
      "During handling of the above exception, another exception occurred:\n",
      "\n",
      "Traceback (most recent call last):\n",
      "  File \"c:\\Users\\Marcos\\miniconda3\\envs\\tf2\\lib\\site-packages\\IPython\\core\\interactiveshell.py\", line 2098, in showtraceback\n",
      "    stb = value._render_traceback_()\n",
      "AttributeError: 'TypeError' object has no attribute '_render_traceback_'\n",
      "\n",
      "During handling of the above exception, another exception occurred:\n",
      "\n",
      "Traceback (most recent call last):\n",
      "  File \"c:\\Users\\Marcos\\miniconda3\\envs\\tf2\\lib\\site-packages\\IPython\\core\\ultratb.py\", line 1101, in get_records\n",
      "    return _fixed_getinnerframes(etb, number_of_lines_of_context, tb_offset)\n",
      "  File \"c:\\Users\\Marcos\\miniconda3\\envs\\tf2\\lib\\site-packages\\IPython\\core\\ultratb.py\", line 248, in wrapped\n",
      "    return f(*args, **kwargs)\n",
      "  File \"c:\\Users\\Marcos\\miniconda3\\envs\\tf2\\lib\\site-packages\\IPython\\core\\ultratb.py\", line 281, in _fixed_getinnerframes\n",
      "    records = fix_frame_records_filenames(inspect.getinnerframes(etb, context))\n",
      "  File \"c:\\Users\\Marcos\\miniconda3\\envs\\tf2\\lib\\inspect.py\", line 1502, in getinnerframes\n",
      "    frameinfo = (tb.tb_frame,) + getframeinfo(tb, context)\n",
      "  File \"c:\\Users\\Marcos\\miniconda3\\envs\\tf2\\lib\\inspect.py\", line 1460, in getframeinfo\n",
      "    filename = getsourcefile(frame) or getfile(frame)\n",
      "  File \"c:\\Users\\Marcos\\miniconda3\\envs\\tf2\\lib\\inspect.py\", line 696, in getsourcefile\n",
      "    if getattr(getmodule(object, filename), '__loader__', None) is not None:\n",
      "  File \"c:\\Users\\Marcos\\miniconda3\\envs\\tf2\\lib\\inspect.py\", line 733, in getmodule\n",
      "    if ismodule(module) and hasattr(module, '__file__'):\n",
      "  File \"c:\\Users\\Marcos\\miniconda3\\envs\\tf2\\lib\\site-packages\\tensorflow\\__init__.py\", line 50, in __getattr__\n",
      "    module = self._load()\n",
      "  File \"c:\\Users\\Marcos\\miniconda3\\envs\\tf2\\lib\\site-packages\\tensorflow\\__init__.py\", line 44, in _load\n",
      "    module = _importlib.import_module(self.__name__)\n",
      "  File \"c:\\Users\\Marcos\\miniconda3\\envs\\tf2\\lib\\importlib\\__init__.py\", line 127, in import_module\n",
      "    return _bootstrap._gcd_import(name[level:], package, level)\n",
      "  File \"<frozen importlib._bootstrap>\", line 1006, in _gcd_import\n",
      "  File \"<frozen importlib._bootstrap>\", line 983, in _find_and_load\n",
      "  File \"<frozen importlib._bootstrap>\", line 965, in _find_and_load_unlocked\n",
      "ModuleNotFoundError: No module named 'tensorflow_core.estimator'\n"
     ]
    }
   ],
   "source": [
    "import tensorflow as tf\n",
    "from tensorflow.keras.layers import MultiHeadAttention\n",
    "from tensorflow.keras.datasets import imdb\n",
    "\n",
    "# Cargar y preparar el conjunto de datos IMDB\n",
    "(train_data, train_labels), (test_data, test_labels) = imdb.load_data(num_words=10000)\n",
    "train_data = tf.keras.preprocessing.sequence.pad_sequences(train_data, maxlen=200)\n",
    "test_data = tf.keras.preprocessing.sequence.pad_sequences(test_data, maxlen=200)\n",
    "\n",
    "# Crear el modelo Transformer\n",
    "model = tf.keras.Sequential([\n",
    "    tf.keras.layers.Embedding(10000, 64, input_length=200),\n",
    "    MultiHeadAttention(num_heads=4, key_dim=64),\n",
    "    tf.keras.layers.GlobalAveragePooling1D(),\n",
    "    tf.keras.layers.Dense(1, activation='sigmoid')\n",
    "])\n",
    "\n",
    "# Compilar el modelo\n",
    "model.compile(optimizer='adam', loss='binary_crossentropy', metrics=['acc'])\n",
    "\n",
    "# Entrenar el modelo\n",
    "model.fit(train_data, train_labels, epochs=4, batch_size=32, validation_split=0.2)\n",
    "\n",
    "# Evaluar el modelo\n",
    "test_loss, test_acc = model.evaluate(test_data, test_labels)\n",
    "print(\"Test accuracy:\", test_acc)\n"
   ]
  }
 ],
 "metadata": {
  "kernelspec": {
   "display_name": "tf2",
   "language": "python",
   "name": "python3"
  },
  "language_info": {
   "codemirror_mode": {
    "name": "ipython",
    "version": 3
   },
   "file_extension": ".py",
   "mimetype": "text/x-python",
   "name": "python",
   "nbconvert_exporter": "python",
   "pygments_lexer": "ipython3",
   "version": "3.7.16"
  },
  "orig_nbformat": 4
 },
 "nbformat": 4,
 "nbformat_minor": 2
}
